Workbook
Name income: #REF!
Name Range_EV: #REF!
Name range_ICE: #REF!

Sheet About
A1: BNoEVC BAU Number of EV Chargers | B1: South Carolina | C1: 46184 | F1: Alabama | G1: AL
B2: =LOOKUP(B1,F1:G50,G1:G50) -> SC | F2: Alaska | G2: AK
A3: Source: | B3: Number of Gas pumps | F3: Arizona | G3: AZ
B4: CleanTechnica | F4: Arkansas | G4: AR
B5: 2018 | F5: California | G5: CA
B6: Stop Comparing the Number of Gas Stations to EV Charging Stations | F6: Colorado | G6: CO
B7: https://cleantechnica.com/2018/03/07/stop-comparing-number-gas-stations-ev-charging-stations/ | F7: Connecticut | G7: CT
F8: Delaware | G8: DE
B9: Number of EVSE Ports | F9: Florida | G9: FL
B10: Alternative Fuels Data Center | F10: Georgia | G10: GA
B11: 2023 | F11: Hawaii | G11: HI
B12: Electric Vehicle Charging Station Locations | F12: Idaho | G12: ID
B13: https://afdc.energy.gov/fuels/electricity_locations.html#/analyze?fuel=ELEC&country=US | F13: Illinois | G13: IL
F14: Indiana | G14: IN
A15: Notes | F15: Iowa | G15: IA
A16: Currency Conversion | B16: 0.89805482 | F16: Kansas | G16: KS
A17: 2019 to 2012 USD | B17: 0.84730413 | F17: Kentucky | G17: KY
A18: 2021 to 2012 USD | B18: 0.785 | F18: Louisiana | G18: LA
A19: 2022 to 2012 USD | F19: Maine | G19: ME
F20: Maryland | G20: MD
A21: We assume that prior to the IIJA or IRA, the number of EV ports would slowly grow with time to equal the number of gas pumps by 2050. | F21: Massachusetts | G21: MA
A22: We adjust our calculations by an estimated number of public charger additions from both the Infrastructure Investment and Jobs Act | F22: Michigan | G22: MI
A23: and the Inflation Reduction Act (see tabs for methodology). | F23: Minnesota | G23: MN
F24: Mississippi | G24: MS
F25: Missouri | G25: MO
F26: Montana | G26: MT
F27: Nebraska | G27: NE
F28: Nevada | G28: NV
F29: New Hampshire | G29: NH
F30: New Jersey | G30: NJ
F31: New Mexico | G31: NM
F32: New York | G32: NY
F33: North Carolina | G33: NC
F34: North Dakota | G34: ND
F35: Ohio | G35: OH
... F50: Wyoming | G50: WY

Sheet EV Charger S-Curve
A1: US Public EV Charging Ports — Historical Data & Logistic (S-Curve) Forecast
A2: Source: AFDC / NREL, Alternative Fuels Data Center (afdc.energy.gov/data/10972). VERIFY against primary source before use.
A4: Logistic Parameters (editable inputs)
A5: L — saturation ceiling (max ports) | B5: 1200000 | C5: ASSUMPTION — not fitted from data; L is essentially unidentifiable from the historical series alone. Scenario this from an external source.
A6: k — growth rate (steepness) | B6: 0.27
A7: t0 — inflection year (midpoint) | B7: 2027 | C7: Logistic: P(t) = L / (1 + EXP(-k*(t - t0)))
A9: Year | B9: Actual Ports (historical) | C9: S-Curve Forecast | D9: YoY Growth (forecast)
A10: 2011 | B10: 5248 | C10: =$B$5/(1+EXP(-$B$6*(A10-$B$7))) -> 15750.382
A11: 2012 | B11: 12726 | C11: =$B$5/(1+EXP(-$B$6*(A11-$B$7))) -> 20548.84 | D11: =C11/C10-1 -> 0.30465661
A12: 2013 | B12: 16619 | C12: =$B$5/(1+EXP(-$B$6*(A12-$B$7))) -> 26776.126 | D12: =C12/C11-1 -> 0.30304808
A13: 2014 | B13: 22247 | C13: =$B$5/(1+EXP(-$B$6*(A13-$B$7))) -> 34834.843 | D13: =C13/C12-1 -> 0.30096648
A14: 2015 | B14: 29968 | C14: =$B$5/(1+EXP(-$B$6*(A14-$B$7))) -> 45225.469 | D14: =C14/C13-1 -> 0.29828254
A15: 2016 | B15: 38543 | C15: =$B$5/(1+EXP(-$B$6*(A15-$B$7))) -> 58559.668 | D15: =C15/C14-1 -> 0.29483827
A16: 2017 | B16: 46218 | C16: =$B$5/(1+EXP(-$B$6*(A16-$B$7))) -> 75568.027 | D16: =C16/C15-1 -> 0.29044495
A17: 2018 | B17: 57386 | C17: =$B$5/(1+EXP(-$B$6*(A17-$B$7))) -> 97096.161 | D17: =C17/C16-1 -> 0.28488415
A18: 2019 | B18: 75808 | C18: =$B$5/(1+EXP(-$B$6*(A18-$B$7))) -> 124080.54 | D18: =C18/C17-1 -> 0.27791399
A19: 2020 | B19: 96521 | C19: =$B$5/(1+EXP(-$B$6*(A19-$B$7))) -> 157493.36 | D19: =C19/C18-1 -> 0.26928333
A20: 2021 | B20: 114715 | C20: =$B$5/(1+EXP(-$B$6*(A20-$B$7))) -> 198245.84 | D20: =C20/C19-1 -> 0.25875681
A21: 2022 | B21: 136307 | C21: =$B$5/(1+EXP(-$B$6*(A21-$B$7))) -> 247044.45 | D21: =C21/C20-1 -> 0.24615195
A22: 2023 | B22: 168388 | C22: =$B$5/(1+EXP(-$B$6*(A22-$B$7))) -> 304207.22 | D22: =C22/C21-1 -> 0.2313866
A23: 2024 | C23: =$B$5/(1+EXP(-$B$6*(A23-$B$7))) -> 369468.59 | D23: =C23/C22-1 -> 0.21452934
A24: 2025 | C24: =$B$5/(1+EXP(-$B$6*(A24-$B$7))) -> 441825.1 | D24: =C24/C23-1 -> 0.19583939
A25: 2026 | C25: =$B$5/(1+EXP(-$B$6*(A25-$B$7))) -> 519488.51 | D25: =C25/C24-1 -> 0.17577864
A26: 2027 | C26: =$B$5/(1+EXP(-$B$6*(A26-$B$7))) -> 600000 | D26: =C26/C25-1 -> 0.15498223
A27: 2028 | C27: =$B$5/(1+EXP(-$B$6*(A27-$B$7))) -> 680511.49 | D27: =C27/C26-1 -> 0.13418581
A28: 2029 | C28: =$B$5/(1+EXP(-$B$6*(A28-$B$7))) -> 758174.9 | D28: =C28/C27-1 -> 0.11412506
A29: 2030 | C29: =$B$5/(1+EXP(-$B$6*(A29-$B$7))) -> 830531.41 | D29: =C29/C28-1 -> 0.095435108
A30: 2031 | C30: =$B$5/(1+EXP(-$B$6*(A30-$B$7))) -> 895792.78 | D30: =C30/C29-1 -> 0.078577853
A31: 2032 | C31: =$B$5/(1+EXP(-$B$6*(A31-$B$7))) -> 952955.55 | D31: =C31/C30-1 -> 0.063812497
A32: 2033 | C32: =$B$5/(1+EXP(-$B$6*(A32-$B$7))) -> 1001754.2 | D32: =C32/C31-1 -> 0.051207637
A33: 2034 | C33: =$B$5/(1+EXP(-$B$6*(A33-$B$7))) -> 1042506.6 | D33: =C33/C32-1 -> 0.04068112
A34: 2035 | C34: =$B$5/(1+EXP(-$B$6*(A34-$B$7))) -> 1075919.5 | D34: =C34/C33-1 -> 0.032050464
A36: Notes:
A37: • Blue cells are inputs you can change; the S-Curve column recalculates automatically.
A38: • 2022 definitional change: ports now include temporarily-unavailable units, creating a small discontinuity.
A39: • Parameters are illustrative, not rigorously fitted. For a real fit, constrain L from a vehicle-stock or published charger-need model and fit k, t0 via Solver/regression.
A40: • This is a starting point for staff review, not a finished EI work product.

Sheet alt_fuel_stations (Jun 5 2026)
A1: Fuel Type Code | B1: State | C1: EV Level1 EVSE Num | D1: EV Level2 EVSE Num | E1: EV DC Fast Count | F1: TOTAL
A2: ELEC | B2: CA | D2: 8 | F2: =SUM(C2:E2) -> 8
A3: ELEC | B3: CA | D3: 1 | F3: =SUM(C3:E3) -> 1
A4: ELEC | B4: CA | D4: 2 | F4: =SUM(C4:E4) -> 2
A5: ELEC | B5: CA | D5: 4 | F5: =SUM(C5:E5) -> 4
A6: ELEC | B6: CA | D6: 26 | F6: =SUM(C6:E6) -> 26
A7: ELEC | B7: CA | D7: 3 | F7: =SUM(C7:E7) -> 3
A8: ELEC | B8: CA | D8: 3 | F8: =SUM(C8:E8) -> 3
A9: ELEC | B9: CA | D9: 1 | F9: =SUM(C9:E9) -> 1
A10: ELEC | B10: CA | D10: 20 | F10: =SUM(C10:E10) -> 20
A11: ELEC | B11: CA | D11: 1 | F11: =SUM(C11:E11) -> 1
A12: ELEC | B12: CA | D12: 2 | F12: =SUM(C12:E12) -> 2
A13: ELEC | B13: CA | D13: 4 | F13: =SUM(C13:E13) -> 4
... A16: ELEC | B16: CA | D16: 3 | F16: =SUM(C16:E16) -> 3
A17: ELEC | B17: CA | C17: 1 | D17: 10 | F17: =SUM(C17:E17) -> 11
A18: ELEC | B18: CA | D18: 4 | F18: =SUM(C18:E18) -> 4
A19: ELEC | B19: CA | D19: 1 | F19: =SUM(C19:E19) -> 1
A20: ELEC | B20: CA | D20: 4 | F20: =SUM(C20:E20) -> 4
A21: ELEC | B21: CA | D21: 2 | F21: =SUM(C21:E21) -> 2
A22: ELEC | B22: CA | D22: 1 | F22: =SUM(C22:E22) -> 1
A23: ELEC | B23: CA | D23: 2 | F23: =SUM(C23:E23) -> 2
A24: ELEC | B24: CA | D24: 2 | F24: =SUM(C24:E24) -> 2
A25: ELEC | B25: CA | D25: 4 | F25: =SUM(C25:E25) -> 4
A26: ELEC | B26: CA | D26: 4 | F26: =SUM(C26:E26) -> 4
A27: ELEC | B27: CA | C27: 12 | D27: 15 | F27: =SUM(C27:E27) -> 27
A28: ELEC | B28: CA | D28: 3 | F28: =SUM(C28:E28) -> 3
A29: ELEC | B29: CA | D29: 6 | F29: =SUM(C29:E29) -> 6
A30: ELEC | B30: CA | D30: 8 | F30: =SUM(C30:E30) -> 8
A31: ELEC | B31: CA | D31: 5 | F31: =SUM(C31:E31) -> 5
A32: ELEC | B32: CA | D32: 4 | F32: =SUM(C32:E32) -> 4
A33: ELEC | B33: CA | C33: 4 | D33: 2 | F33: =SUM(C33:E33) -> 6
A34: ELEC | B34: CA | D34: 1 | F34: =SUM(C34:E34) -> 1
A35: ELEC | B35: CA | D35: 2 | F35: =SUM(C35:E35) -> 2
A36: ELEC | B36: CA | D36: 3 | F36: =SUM(C36:E36) -> 3
A37: ELEC | B37: CA | D37: 3 | F37: =SUM(C37:E37) -> 3
A38: ELEC | B38: CA | C38: 1 | D38: 3 | F38: =SUM(C38:E38) -> 4
A39: ELEC | B39: CA | D39: 2 | F39: =SUM(C39:E39) -> 2
A40: ELEC | B40: CA | C40: 1 | D40: 2 | F40: =SUM(C40:E40) -> 3
A41: ELEC | B41: CA | D41: 1 | F41: =SUM(C41:E41) -> 1
A42: ELEC | B42: CA | D42: 2 | F42: =SUM(C42:E42) -> 2
...

Sheet 2022
A1: Station Counts by State and Fuel Type
A2: State | B2: Electrica
B3: (stations / charging outlets
B4: Level 1 / Level 2 / DC Fast)
A5: Alabama | B5: 326 | C5: 848
B6: 35 | C6: 574 | D6: 239
A7: Alaska | B7: 62 | C7: 115
B8: 3 | C8: 81 | D8: 31
A9: Arizona | B9: 977 | C9: 2638
B10: 9 | C10: 2036 | D10: 593
A11: Arkansas | B11: 222 | C11: 598
B12: 3 | C12: 516 | D12: 79
A13: California | B13: 14616 | C13: 43400
B14: 546 | C14: 34359 | D14: 8465
A15: Colorado | B15: 1788 | C15: 4411
B16: 90 | C16: 3588 | D16: 733
A17: Connecticut | B17: 593 | C17: 1638
B18: 67 | C18: 1220 | D18: 349
A19: Delaware | B19: 156 | C19: 367
B20: 5 | C20: 257 | D20: 105
A21: District of Columbia | B21: 300 | C21: 970
B22: 43 | C22: 889 | D22: 38
A23: Florida | B23: 2913 | C23: 7802
B24: 364 | C24: 5823 | D24: 1615
A25: Georgia | B25: 1550 | C25: 4121
B26: 230 | C26: 3097 | D26: 794
A27: Hawaii | B27: 406 | C27: 940
B28: 30 | C28: 833 | D28: 77
A29: Idaho | B29: 155 | C29: 382
B30: 10 | C30: 285 | D30: 87
A31: Illinois | B31: 1328 | C31: 3315
B32: 50 | C32: 2593 | D32: 672
A33: Indiana | B33: 400 | C33: 1088
B34: 8 | C34: 743 | D34: 337
A35: Iowa | B35: 305 | C35: 659
B36: 4 | C36: 420 | D36: 235
A37: Kansas | B37: 491 | C37: 1047
B38: 14 | C38: 878 | D38: 155
A39: Kentucky | B39: 252 | C39: 616
B40: 24 | C40: 481 | D40: 111
...

Sheet calcs
A1: STATE | B1: =About!B2 -> SC | C1: =About!B1 -> South Carolina
B3: 2022 | C3: 2025
A4: EV charger | B4: =SUMIFS('2022'!C:C,'2022'!A:A,calcs!C1) -> 987 | C4: =SUMIFS('alt_fuel_stations (Jun 5 2026)'!F:F,'alt_fuel_stations (Jun 5 2026)'!B:B,calcs!B1) -> 2083
B6: 2022 | C6: 2023 | D6: 2024 | E6: 2025 | F6: 2026 | G6: 2027 | H6: 2028 | I6: 2029 | J6: 2030 | K6: 2031 | L6: 2032 | M6: 2033 | N6: 2034 | O6: 2035
A7: GROWTH | B7: {=TRANSPOSE('EV Charger S-Curve'!D21:D34)} -> 0.24615195 | C7: 0.2313866 | D7: 0.21452934 | E7: 0.19583939 | F7: 0.17577864 | G7: 0.15498223 | H7: 0.13418581 | I7: 0.11412506 | J7: 0.095435108 | K7: 0.078577853 | L7: 0.063812497 | M7: 0.051207637 | N7: 0.04068112 | O7: 0.032050464
B10: 2022 | C10: 2023 | D10: 2024 | E10: 2025 | F10: 2026 | G10: 2027 | H10: 2028 | I10: 2029 | J10: 2030 | K10: 2031 | L10: 2032 | M10: 2033 | N10: 2034 | O10: 2035 | P10: 2036 | Q10: 2037 | R10: 2038 | S10: 2039 | T10: 2040 | U10: 2041 | V10: 2042 | W10: 2043 | X10: 2044 | Y10: 2045 | Z10: 2046 | AA10: 2047 | AB10: 2048 | AC10: 2049 | AD10: 2050
A11: EV charger | B11: =_xlfn.FORECAST.ETS(B10,$B$4:$C$4,$B$3:$C$3) -> 987 | C11: =_xlfn.FORECAST.ETS(C10,$B$4:$C$4,$B$3:$C$3) -> 1352.3333 | D11: =ROUND(C11*(1+'EV Charger S-Curve'!D22),0) -> 1665 | E11: =C4 -> 2083 | F11: =ROUND(E11*(1+F7),0) -> 2449 | G11: =ROUND(F11*(1+G7),0) -> 2829 | H11: =ROUND(G11*(1+H7),0) -> 3209 | I11: =ROUND(H11*(1+I7),0) -> 3575 | J11: =ROUND(I11*(1+J7),0) -> 3916 | K11: =ROUND(J11*(1+K7),0) -> 4224 | L11: =ROUND(K11*(1+L7),0) -> 4494 | M11: =ROUND(L11*(1+M7),0) -> 4724 | ... O11: =ROUND(N11*(1+O7),0) -> 5074 | P11: =ROUND(_xlfn.FORECAST.ETS(P10,$J$11:$O$11,$J$10:$O$10),0) -> 5298 | Q11: =ROUND(_xlfn.FORECAST.ETS(Q10,$J$11:$O$11,$J$10:$O$10),0) -> 5523 | R11: =ROUND(_xlfn.FORECAST.ETS(R10,$J$11:$O$11,$J$10:$O$10),0) -> 5747 | S11: =ROUND(_xlfn.FORECAST.ETS(S10,$J$11:$O$11,$J$10:$O$10),0) -> 5971 | T11: =ROUND(_xlfn.FORECAST.ETS(T10,$J$11:$O$11,$J$10:$O$10),0) -> 6195 | U11: =ROUND(_xlfn.FORECAST.ETS(U10,$J$11:$O$11,$J$10:$O$10),0) -> 6419 | V11: =ROUND(_xlfn.FORECAST.ETS(V10,$J$11:$O$11,$J$10:$O$10),0) -> 6644 | W11: =ROUND(_xlfn.FORECAST.ETS(W10,$J$11:$O$11,$J$10:$O$10),0) -> 6868 | ... AD11: =ROUND(_xlfn.FORECAST.ETS(AD10,$J$11:$O$11,$J$10:$O$10),0) -> 8437

Sheet BNoEVC
A1: Number of chargers | B1: 2024 | C1: 2025 | D1: 2026 | E1: 2027 | F1: 2028 | G1: 2029 | H1: 2030 | I1: 2031 | J1: 2032 | K1: 2033 | L1: 2034 | M1: 2035 | N1: 2036 | O1: 2037 | P1: 2038 | Q1: 2039 | R1: 2040 | S1: 2041 | T1: 2042 | U1: 2043 | V1: 2044 | W1: 2045 | X1: 2046 | Y1: 2047 | Z1: 2048 | AA1: 2049 | AB1: 2050
A2: BAU EV Chargers | B2: =calcs!D11 -> 1665 | C2: =calcs!E11 -> 2083 | D2: =calcs!F11 -> 2449 | E2: =calcs!G11 -> 2829 | F2: =calcs!H11 -> 3209 | G2: =calcs!I11 -> 3575 | H2: =calcs!J11 -> 3916 | I2: =calcs!K11 -> 4224 | ... AB2: =calcs!AD11 -> 8437
